<?xml version="1.0"?>
<robot xmlns:xacro="http://www.ros.org/wiki/xacro" name="Lidar">

  <xacro:macro name="Lidar" params="name inertial_xyz joint_xyz">
    <link name="lidar">
    <inertial>
      <origin
        xyz="0.00676628412110622 -0.0073497547966201 9.204265617406E-05"
        rpy="0 0 0" />
      <mass
        value="1.32944589754502" />
      <inertia
        ixx="0.000612752010300123"
        ixy="0.000158232462510536"
        ixz="8.01141141656571E-07"
        iyy="0.0010957461492681"
        iyz="3.09663447837291E-06"
        izz="0.000957691135206996" />
    </inertial>
    <visual>
      <origin
        xyz="0 0 0"
        rpy="0 0 0" />
      <geometry>
        <mesh
          filename="package://mobot_v2/meshes/lidar.STL" />
      </geometry>
      <material name="">
        <color
          rgba="0.792156862745098 0.819607843137255 0.933333333333333 1" />
      </material>
    </visual>
    <collision>
      <origin
        xyz="0 0 0"
        rpy="0 0 0" />
      <geometry>
        <mesh
          filename="package://mobot_v2/meshes/lidar.STL" />
      </geometry>
    </collision>
  </link>
  
  <joint
    name="lidar-jt"
    type="continuous">
    <origin
      xyz="-0.116239998050096 0.0332696535569434 -0.107718855962475"
      rpy="-1.5707963267949 0 1.5707963267949" />
    <parent
      link="Base_origin" />
    <child
      link="lidar" />
    <axis
      xyz="0 1 0" />
    <limit
      lower="0"
      upper="0"
      effort="0"
      velocity="0" />
  </joint>
</xacro:macro>

</robot>
